<robot name="asu_robot">



<link name="world">
</link>



    <link name="base_link">
        <visual>
            <origin xyz="0 0 0" rpy="0 0 0" />
            <geometry>
                <box size="1 1 1" />
            </geometry>
        </visual>
        

    </link>
    
    
    
    <link name="link_1">
        <visual>
            <origin xyz="0 0 0.2" rpy="0 0 0" />
            <geometry>
                <box size="0.1 0.1 0.4" />
            </geometry>
        </visual>
       
        
    </link>
    
    
    
    <link name="link_2">
        <visual>
            <origin xyz="0.2 0 0" rpy="0 0 0" />
            <geometry>
                <box size="0.4 0.1 0.1" />
            </geometry>
        </visual>
      

    </link>
    
    
    
    <link name="link_3">
        <visual>
            <origin xyz="0.15 0 0" rpy="0 0 0" />
            <geometry>
                <box size="0.3 0.1 0.1" />
            </geometry>
        </visual>
       

    </link>
    
    
    
    <link name="link_4">
        <visual>
            <origin xyz="0.1 0 0" rpy="0 0 0" />
            <geometry>
                <box size="0.2 0.1 0.1" />
            </geometry>
        </visual>
       

    </link>
    
    
    
    <link name="link_5">
        <visual>
            <origin xyz="0.1 0 0" rpy="0 0 0" />
            <geometry>
                <box size="0.2 0.1 0.1" />
            </geometry>
        </visual>
       

    </link>
    
    
    
    <link name="link_6">
        <visual>
            <origin xyz="0.1 0 0" rpy="0 0 0" />
            <geometry>
                <box size="0.2 0.1 0.1" />
            </geometry>
        </visual>
      

    </link>
    
    
    
    <link name="EF">
        <visual>
            <origin xyz="-0.05 0 0" rpy="0 0 0" />
            <geometry>
                <box size="0.1 0.05 0.05" />
            </geometry>
        </visual>
       

    </link>
    
    
    
    
    
    
    <joint name="world_joint" type="fixed">
        <origin xyz="0 0 0.1" rpy="0 0 0" />
        <parent link="world" />
        <child link="base_link" />
        <axis xyz="0 0 0" />
        <limit lower="-3" upper="3" effort="20" velocity="1" />
    </joint>
    
    
    
    <joint name="joint_1" type="revolute">
        <origin xyz="0 0 0.1" rpy="0 0 0" />
        <parent link="base_link" />
        <child link="link_1" />
        <axis xyz="0 0 1" />
        <limit lower="-3" upper="3" effort="20" velocity="1" />
    </joint>
    
    
    
    <joint name="joint_2" type="revolute">
        <origin xyz="0 0 0.4" rpy="0 0 0" />
        <parent link="link_1" />
        <child link="link_2" />
        <axis xyz="0 1 0" />
        <limit lower="-3" upper="3" effort="20" velocity="1" />
    </joint>
    
    
    
    <joint name="joint_3" type="revolute">
        <origin xyz="0.4 0 0" rpy="0 0 0" />
        <parent link="link_2" />
        <child link="link_3" />
        <axis xyz="0 1 0" />
        <limit lower="-3" upper="3" effort="20" velocity="1" />
    </joint>
    
    
    
    <joint name="joint_4" type="revolute">
        <origin xyz="0.3 0 0" rpy="0 0 0" />
        <parent link="link_3" />
        <child link="link_4" />
        <axis xyz="1 0 0" />
        <limit lower="-3" upper="3" effort="20" velocity="1" />
    </joint>
    
    
    
    <joint name="joint_5" type="revolute">
        <origin xyz="0.2 0 0" rpy="0 0 0" />
        <parent link="link_4" />
        <child link="link_5" />
        <axis xyz="0 0 1" />
        <limit lower="-3" upper="3" effort="20" velocity="1" />
    </joint>
    
    
    
    <joint name="joint_6" type="revolute">
        <origin xyz="0.2 0 0" rpy="0 0 0" />
        <parent link="link_5" />
        <child link="link_6" />
        <axis xyz="1 0 0" />
        <limit lower="-3" upper="3" effort="20" velocity="1" />
    </joint>
    
    
    
    <joint name="joint_7" type="fixed">
        <origin xyz="0.3 0 0" rpy="0 0 0" />
        <parent link="link_6" />
        <child link="EF" />
        <axis xyz="0 0 0" />
        <limit lower="-3" upper="3" effort="20" velocity="1" />
    </joint>
    
    
    
  
    
    
    
</robot>
